<?xml version="1.0" encoding="utf-8"?>
<!-- This URDF was automatically created by SolidWorks to URDF Exporter! Originally created by Stephen Brawner (brawner@gmail.com) 
     Commit Version: 1.6.0-1-g15f4949  Build Version: 1.6.7594.29634
     For more information, please see http://wiki.ros.org/sw_urdf_exporter -->
<robot
  name="ensambFinal2">
  <link
    name="base_link">
    <inertial>
      <origin
        xyz="6.08786476785639E-09 8.07619537823712E-06 0.144032084321569"
        rpy="0 0 0" />
      <mass
        value="0.378441862038391" />
      <inertia
        ixx="0.00031446282782493"
        ixy="7.0003996665484E-12"
        ixz="1.16261693490524E-12"
        iyy="0.00070862756951546"
        iyz="8.42367440324371E-11"
        izz="0.00102261356077474" />
    </inertial>
    <visual>
      <origin
        xyz="0 0 0"
        rpy="0 0 0" />
      <geometry>
        <mesh
          filename="package://ensambFinal2/meshes/base_link.STL" />
      </geometry>
      <material
        name="">
        <color
          rgba="1 1 1 1" />
      </material>
    </visual>
    <collision>
      <origin
        xyz="0 0 0"
        rpy="0 0 0" />
      <geometry>
        <mesh
          filename="package://ensambFinal2/meshes/base_link.STL" />
      </geometry>
    </collision>
  </link>
  <link
    name="leg_link">
    <inertial>
      <origin
        xyz="-2.19098739151491E-10 -4.55608883953573E-10 -0.0473020063077466"
        rpy="0 0 0" />
      <mass
        value="0.054089183968301" />
      <inertia
        ixx="0.000125380501803204"
        ixy="4.49602259312539E-14"
        ixz="-1.34427160567444E-13"
        iyy="0.000125380501775018"
        iyz="-1.78463707729355E-13"
        izz="7.07252921065922E-05" />
    </inertial>
    <visual>
      <origin
        xyz="0 0 0"
        rpy="0 0 0" />
      <geometry>
        <mesh
          filename="package://ensambFinal2/meshes/leg_link.STL" />
      </geometry>
      <material
        name="">
        <color
          rgba="0.180392156862745 0.180392156862745 0.180392156862745 1" />
      </material>
    </visual>
    <collision>
      <origin
        xyz="0 0 0"
        rpy="0 0 0" />
      <geometry>
        <mesh
          filename="package://ensambFinal2/meshes/leg_link.STL" />
      </geometry>
    </collision>
  </link>
  <joint
    name="leg_link_join"
    type="fixed">
    <origin
      xyz="0 0 0.132"
      rpy="0 0 0" />
    <parent
      link="base_link" />
    <child
      link="leg_link" />
    <axis
      xyz="0 0 0" />
  </joint>
  <link
    name="battery_link">
    <inertial>
      <origin
        xyz="2.2204E-16 0 0.021"
        rpy="0 0 0" />
      <mass
        value="0.19453" />
      <inertia
        ixx="4.2923E-05"
        ixy="-1.0651E-17"
        ixz="-6.7665E-21"
        iyy="0.00041696"
        iyz="4.248E-20"
        izz="0.00040304" />
    </inertial>
    <visual>
      <origin
        xyz="0 0 0"
        rpy="0 0 0" />
      <geometry>
        <mesh
          filename="package://ensambFinal2/meshes/battery_link.STL" />
      </geometry>
      <material
        name="">
        <color
          rgba="1 0 0 1" />
      </material>
    </visual>
    <collision>
      <origin
        xyz="0 0 0"
        rpy="0 0 0" />
      <geometry>
        <mesh
          filename="package://ensambFinal2/meshes/battery_link.STL" />
      </geometry>
    </collision>
  </link>
  <joint
    name="battery_link_joint"
    type="fixed">
    <origin
      xyz="-0.0254345337045486 -0.000222161622824846 0.09"
      rpy="0 0 0" />
    <parent
      link="base_link" />
    <child
      link="battery_link" />
    <axis
      xyz="0 0 0" />
  </joint>
  <link
    name="jetson_link">
    <inertial>
      <origin
        xyz="-0.0061136923619951 -4.44089209850063E-16 -0.0193380249795172"
        rpy="0 0 0" />
      <mass
        value="0.492086592201425" />
      <inertia
        ixx="0.000649241398696012"
        ixy="2.23616698075135E-18"
        ixz="-3.21084449631311E-06"
        iyy="0.000555306717180541"
        iyz="1.7818410638166E-20"
        izz="0.00108977762498107" />
    </inertial>
    <visual>
      <origin
        xyz="0 0 0"
        rpy="0 0 0" />
      <geometry>
        <mesh
          filename="package://ensambFinal2/meshes/jetson_link.STL" />
      </geometry>
      <material
        name="">
        <color
          rgba="0.792156862745098 0.819607843137255 0.933333333333333 1" />
      </material>
    </visual>
    <collision>
      <origin
        xyz="0 0 0"
        rpy="0 0 0" />
      <geometry>
        <mesh
          filename="package://ensambFinal2/meshes/jetson_link.STL" />
      </geometry>
    </collision>
  </link>
  <joint
    name="jetson_link_joint"
    type="fixed">
    <origin
      xyz="0.00570216508420418 0.000181695463438825 0.210999999999999"
      rpy="0 0 0" />
    <parent
      link="base_link" />
    <child
      link="jetson_link" />
    <axis
      xyz="0 0 0" />
  </joint>
  <link
    name="d435_link">
    <inertial>
      <origin
        xyz="0.081851 -0.0015739 0.14489"
        rpy="0 0 0" />
      <mass
        value="0.043919" />
      <inertia
        ixx="2.6619E-05"
        ixy="-3.8865E-08"
        ixz="-7.8416E-10"
        iyy="3.7905E-06"
        iyz="-3.5641E-10"
        izz="2.6815E-05" />
    </inertial>
    <visual>
      <origin
        xyz="0 0 0"
        rpy="0 0 0" />
      <geometry>
        <mesh
          filename="package://ensambFinal2/meshes/d435_link.STL" />
      </geometry>
      <material
        name="">
        <color
          rgba="0.79216 0.81961 0.93333 1" />
      </material>
    </visual>
    <collision>
      <origin
        xyz="0 0 0"
        rpy="0 0 0" />
      <geometry>
        <mesh
          filename="package://ensambFinal2/meshes/d435_link.STL" />
      </geometry>
    </collision>
  </link>
  <joint
    name="d435_link_joint"
    type="fixed">
    <origin
      xyz="0 0 0"
      rpy="0 0 0" />
    <parent
      link="base_link" />
    <child
      link="d435_link" />
    <axis
      xyz="0 0 0" />
  </joint>
  <link
    name="t265_link">
    <inertial>
      <origin
        xyz="0 0.0084958 0.0057875"
        rpy="0 0 0" />
      <mass
        value="0.02522" />
      <inertia
        ixx="2.3287E-05"
        ixy="6.9483E-21"
        ixz="-6.9902E-23"
        iyy="1.407E-06"
        iyz="-7.9779E-08"
        izz="2.4276E-05" />
    </inertial>
    <visual>
      <origin
        xyz="0 0 0"
        rpy="0 0 0" />
      <geometry>
        <mesh
          filename="package://ensambFinal2/meshes/t265_link.STL" />
      </geometry>
      <material
        name="">
        <color
          rgba="0.79216 0.81961 0.93333 1" />
      </material>
    </visual>
    <collision>
      <origin
        xyz="0 0 0"
        rpy="0 0 0" />
      <geometry>
        <mesh
          filename="package://ensambFinal2/meshes/t265_link.STL" />
      </geometry>
    </collision>
  </link>
  <joint
    name="t265_link_joint"
    type="fixed">
    <origin
      xyz="0.0824052505915143 -0.00862818550105171 0.118529424882819"
      rpy="0 0 0" />
    <parent
      link="base_link" />
    <child
      link="t265_link" />
    <axis
      xyz="0 0 0" />
  </joint>
  <link
    name="front_arm_link">
    <inertial>
      <origin
        xyz="-0.0089565 -0.09809 -0.0071207"
        rpy="0 0 0" />
      <mass
        value="0.084665" />
      <inertia
        ixx="0.00016909"
        ixy="-6.9045E-14"
        ixz="-8.09E-06"
        iyy="0.00016909"
        iyz="2.1627E-10"
        izz="0.00033135" />
    </inertial>
    <visual>
      <origin
        xyz="0 0 0"
        rpy="0 0 0" />
      <geometry>
        <mesh
          filename="package://ensambFinal2/meshes/front_arm_link.STL" />
      </geometry>
      <material
        name="">
        <color
          rgba="1 0 0 1" />
      </material>
    </visual>
    <collision>
      <origin
        xyz="0 0 0"
        rpy="0 0 0" />
      <geometry>
        <mesh
          filename="package://ensambFinal2/meshes/front_arm_link.STL" />
      </geometry>
    </collision>
  </link>
  <joint
    name="front_arm_link_joint"
    type="fixed">
    <origin
      xyz="0.0980914901926789 0.0980914949967717 0.170999999999999"
      rpy="0 0 0" />
    <parent
      link="base_link" />
    <child
      link="front_arm_link" />
    <axis
      xyz="0 0 0" />
  </joint>
  <link
    name="back_arm_link">
    <inertial>
      <origin
        xyz="0.0089565 0.09809 -0.0071207"
        rpy="0 0 0" />
      <mass
        value="0.084665" />
      <inertia
        ixx="0.00016909"
        ixy="1.9305E-13"
        ixz="8.09E-06"
        iyy="0.00016909"
        iyz="-2.1627E-10"
        izz="0.00033135" />
    </inertial>
    <visual>
      <origin
        xyz="0 0 0"
        rpy="0 0 0" />
      <geometry>
        <mesh
          filename="package://ensambFinal2/meshes/back_arm_link.STL" />
      </geometry>
      <material
        name="">
        <color
          rgba="1 1 1 1" />
      </material>
    </visual>
    <collision>
      <origin
        xyz="0 0 0"
        rpy="0 0 0" />
      <geometry>
        <mesh
          filename="package://ensambFinal2/meshes/back_arm_link.STL" />
      </geometry>
    </collision>
  </link>
  <joint
    name="back_arm_link_joint"
    type="fixed">
    <origin
      xyz="-0.0980914901926772 -0.0980914949967722 0.170999999999999"
      rpy="0 0 0" />
    <parent
      link="base_link" />
    <child
      link="back_arm_link" />
    <axis
      xyz="0 0 0" />
  </joint>
  <link
    name="prop_guard_link">
    <inertial>
      <origin
        xyz="3.3619E-05 -3.3452E-06 0.0015"
        rpy="0 0 0" />
      <mass
        value="0.084635" />
      <inertia
        ixx="0.00040912"
        ixy="1.0752E-12"
        ixz="-1.1324E-13"
        iyy="0.00040932"
        iyz="1.157E-13"
        izz="0.00081832" />
    </inertial>
    <visual>
      <origin
        xyz="0 0 0"
        rpy="0 0 0" />
      <geometry>
        <mesh
          filename="package://ensambFinal2/meshes/prop_guard_link.STL" />
      </geometry>
      <material
        name="">
        <color
          rgba="0.79216 0.81961 0.93333 1" />
      </material>
    </visual>
    <collision>
      <origin
        xyz="0 0 0"
        rpy="0 0 0" />
      <geometry>
        <mesh
          filename="package://ensambFinal2/meshes/prop_guard_link.STL" />
      </geometry>
    </collision>
  </link>
  <joint
    name="prop_guard_link_joint"
    type="fixed">
    <origin
      xyz="0 3.69664538357739E-05 0.170999999999999"
      rpy="0 0 0" />
    <parent
      link="base_link" />
    <child
      link="prop_guard_link" />
    <axis
      xyz="0 0 0" />
  </joint>
  <link
    name="motor_link">
    <inertial>
      <origin
        xyz="0.00077732 -0.0001817 0.013912"
        rpy="0 0 0" />
      <mass
        value="0.057143" />
      <inertia
        ixx="5.7889E-06"
        ixy="-5.294E-23"
        ixz="-3.6525E-22"
        iyy="5.7889E-06"
        iyz="2.1435E-22"
        izz="5.0078E-06" />
    </inertial>
    <visual>
      <origin
        xyz="0 0 0"
        rpy="0 0 0" />
      <geometry>
        <mesh
          filename="package://ensambFinal2/meshes/motor_link.STL" />
      </geometry>
      <material
        name="">
        <color
          rgba="0.79216 0.81961 0.93333 1" />
      </material>
    </visual>
    <collision>
      <origin
        xyz="0 0 0"
        rpy="0 0 0" />
      <geometry>
        <mesh
          filename="package://ensambFinal2/meshes/motor_link.STL" />
      </geometry>
    </collision>
  </link>
  <joint
    name="motor_link_joint"
    type="continuous">
    <origin
      xyz="-0.000777316557265428 0.000181695463438825 0.172999999999999"
      rpy="0 0 0" />
    <parent
      link="base_link" />
    <child
      link="motor_link" />
    <axis
      xyz="0 0 1" />
  </joint>
  <link
    name="rotor1">
    <inertial>
      <origin
        xyz="-2.4425E-15 4.4409E-16 -0.0036905"
        rpy="0 0 0" />
      <mass
        value="0.01285" />
      <inertia
        ixx="4.2273E-05"
        ixy="-6.5451E-06"
        ixz="-8.6572E-21"
        iyy="1.721E-06"
        iyz="4.9693E-21"
        izz="4.3878E-05" />
    </inertial>
    <visual>
      <origin
        xyz="0 0 0"
        rpy="0 0 0" />
      <geometry>
        <mesh
          filename="package://ensambFinal2/meshes/rotor1.STL" />
      </geometry>
      <material
        name="">
        <color
          rgba="1 1 1 1" />
      </material>
    </visual>
    <collision>
      <origin
        xyz="0 0 0"
        rpy="0 0 0" />
      <geometry>
        <mesh
          filename="package://ensambFinal2/meshes/rotor1.STL" />
      </geometry>
    </collision>
  </link>
  <joint
    name="rotor1_joint"
    type="continuous">
    <origin
      xyz="0.15988 0.15988 0.21"
      rpy="0 0 0" />
    <parent
      link="base_link" />
    <child
      link="rotor1" />
    <axis
      xyz="-0.98636 0.16459 0" />
  </joint>
  <link
    name="rotor2">
    <inertial>
      <origin
        xyz="-2.4425E-15 0 -0.0036905"
        rpy="0 0 0" />
      <mass
        value="0.01285" />
      <inertia
        ixx="4.2273E-05"
        ixy="-6.5451E-06"
        ixz="-9.1512E-21"
        iyy="1.721E-06"
        iyz="5.2592E-21"
        izz="4.3878E-05" />
    </inertial>
    <visual>
      <origin
        xyz="0 0 0"
        rpy="0 0 0" />
      <geometry>
        <mesh
          filename="package://ensambFinal2/meshes/rotor2.STL" />
      </geometry>
      <material
        name="">
        <color
          rgba="1 1 1 1" />
      </material>
    </visual>
    <collision>
      <origin
        xyz="0 0 0"
        rpy="0 0 0" />
      <geometry>
        <mesh
          filename="package://ensambFinal2/meshes/rotor2.STL" />
      </geometry>
    </collision>
  </link>
  <joint
    name="rotor2_joint"
    type="continuous">
    <origin
      xyz="-0.15988 -0.15988 0.21"
      rpy="0 0 0" />
    <parent
      link="base_link" />
    <child
      link="rotor2" />
    <axis
      xyz="-0.98636 0.16459 0" />
  </joint>
  <link
    name="rotor3">
    <inertial>
      <origin
        xyz="8.8818E-16 2.6645E-15 -0.0036905"
        rpy="0 0 0" />
      <mass
        value="0.01285" />
      <inertia
        ixx="4.2018E-05"
        ixy="-7.2884E-06"
        ixz="2.9856E-21"
        iyy="1.9761E-06"
        iyz="8.258E-21"
        izz="4.3878E-05" />
    </inertial>
    <visual>
      <origin
        xyz="0 0 0"
        rpy="0 0 0" />
      <geometry>
        <mesh
          filename="package://ensambFinal2/meshes/rotor3.STL" />
      </geometry>
      <material
        name="">
        <color
          rgba="1 1 1 1" />
      </material>
    </visual>
    <collision>
      <origin
        xyz="0 0 0"
        rpy="0 0 0" />
      <geometry>
        <mesh
          filename="package://ensambFinal2/meshes/rotor3.STL" />
      </geometry>
    </collision>
  </link>
  <joint
    name="rotor3_joint"
    type="continuous">
    <origin
      xyz="0.15988 -0.15988 0.21"
      rpy="0 0 0" />
    <parent
      link="base_link" />
    <child
      link="rotor3" />
    <axis
      xyz="-0.98636 0.16459 0" />
  </joint>
  <link
    name="rotor4">
    <inertial>
      <origin
        xyz="0 0 0"
        rpy="0 0 0" />
      <mass
        value="0" />
      <inertia
        ixx="0"
        ixy="0"
        ixz="0"
        iyy="0"
        iyz="0"
        izz="0" />
    </inertial>
    <visual>
      <origin
        xyz="0 0 0"
        rpy="0 0 0" />
      <geometry>
        <mesh
          filename="package://ensambFinal2/meshes/rotor4.STL" />
      </geometry>
      <material
        name="">
        <color
          rgba="1 1 1 1" />
      </material>
    </visual>
    <collision>
      <origin
        xyz="0 0 0"
        rpy="0 0 0" />
      <geometry>
        <mesh
          filename="package://ensambFinal2/meshes/rotor4.STL" />
      </geometry>
    </collision>
  </link>
  <joint
    name="rotor4_joint"
    type="continuous">
    <origin
      xyz="-0.15988 0.15988 0.21"
      rpy="0 0 0" />
    <parent
      link="base_link" />
    <child
      link="rotor4" />
    <axis
      xyz="-0.98636 0.16459 0" />
  </joint>
</robot>